<sdf version='1.11'>
  <model name='linkage'>
    <link name='link A'>
      <inertial>
        <pose>0 0 0 0 0 0</pose>
        <mass>0.5</mass>
        <inertia>
          <ixx>0.5</ixx>
          <ixy>0</ixy>
          <ixz>0</ixz>
          <iyy>0.5</iyy>
          <iyz>0</iyz>
          <izz>0.5</izz>
        </inertia>
      </inertial>
      <visual name='link A_visual'>
        <pose>0 0 0 0 0 0</pose>
        <geometry>
          <box>
            <size>0.5 0.5 0.10000000000000001</size>
          </box>
        </geometry>
        <material>
          <diffuse>0.125 0.125 0.125 1</diffuse>
          <ambient>0.125 0.125 0.125 1</ambient>
        </material>
      </visual>
    </link>
    <joint name='joint A' type='revolute'>
      <pose relative_to='link A'>0 0 -0.050000000000000003 0 0 0</pose>
      <parent>link A</parent>
      <child>link B</child>
      <axis>
        <xyz>0 1 0</xyz>
        <limit>
          <lower>-inf</lower>
          <upper>inf</upper>
        </limit>
        <dynamics>
          <spring_reference>0</spring_reference>
          <spring_stiffness>0</spring_stiffness>
        </dynamics>
      </axis>
    </joint>
    <link name='link B'>
      <pose relative_to='joint A'>0 0 0 0 0 0</pose>
      <inertial>
        <pose>0 0 -0.5 0 0 0</pose>
        <mass>0.5</mass>
        <inertia>
          <ixx>0.5</ixx>
          <ixy>0</ixy>
          <ixz>0</ixz>
          <iyy>0.5</iyy>
          <iyz>0</iyz>
          <izz>0.5</izz>
        </inertia>
      </inertial>
      <visual name='link B_visual'>
        <pose>0 0 -0.5 0 0 0</pose>
        <geometry>
          <cylinder>
            <length>1</length>
            <radius>0.050000000000000003</radius>
          </cylinder>
        </geometry>
        <material>
          <diffuse>0.37500003 0.37500003 0.37500003 1</diffuse>
          <ambient>0.37500003 0.37500003 0.37500003 1</ambient>
        </material>
      </visual>
    </link>
    <joint name='joint B' type='revolute'>
      <pose relative_to='link B'>0 0 -1 0 0 0</pose>
      <parent>link B</parent>
      <child>link C</child>
      <axis>
        <xyz>0 1 0</xyz>
        <limit>
          <lower>-inf</lower>
          <upper>inf</upper>
        </limit>
        <dynamics>
          <damping>0.002</damping>
          <friction>0</friction>
          <spring_reference>0</spring_reference>
          <spring_stiffness>0</spring_stiffness>
        </dynamics>
      </axis>
    </joint>
    <link name='link C'>
      <pose relative_to='joint B'>0 0 0 0 0 0</pose>
      <inertial>
        <pose>0 0 -0.5 0 0 0</pose>
        <mass>0.5</mass>
        <inertia>
          <ixx>0.5</ixx>
          <ixy>0</ixy>
          <ixz>0</ixz>
          <iyy>0.5</iyy>
          <iyz>0</iyz>
          <izz>0.5</izz>
        </inertia>
      </inertial>
      <visual name='link C_visual'>
        <pose>0 0 -0.5 0 0 0</pose>
        <geometry>
          <cylinder>
            <length>1</length>
            <radius>0.050000000000000003</radius>
          </cylinder>
        </geometry>
        <material>
          <diffuse>0.625 0.625 0.625 1</diffuse>
          <ambient>0.625 0.625 0.625 1</ambient>
        </material>
      </visual>
    </link>
  </model>
</sdf>
